Workbook

Sheet Титул
B2: ="Финансовая модель проекта "&Проект -> Финансовая модель проекта «Наследие»
B3: Визуальная новелла на основе фольклора народов России
B4: Версия для защиты перед инвестором / банком / грантовым комитетом
B6: Ключевые параметры
B7: Период планирования | C7: =CHOOSE(MONTH(Дата_начала),"Январь","Февраль","Март","Апрель","Май","Июнь","Июль","Август","Сентябрь","Октябрь","Ноябрь","Декабрь")&" "&YEAR(Дата_начала)&" - "&CHOOSE(MONTH(DATE(YEAR(Дата_начала),MONTH(Дата_начала)+11,1)),"Январь","Февраль","Март","Апрель","Май","Июнь","Июль","Август","Сентябрь","Октябрь","Ноябрь","Декабрь")&" "&YEAR(DATE(YEAR(Дата_начала),MONTH(Дата_начала)+11,1))&" (12 месяцев)" -> Сентябрь 2026 - Август 2027 (12 месяцев)
B8: Бюджет проекта | C8: =FIXED(Собств_капитал,0)&" ₽ собственных средств команды (по "&FIXED(Взнос_участника,0)&" ₽ с человека)" -> 200,000 ₽ собственных средств команды (по 50,000 ₽ с человека)
B9: Команда | C9: =Участников&" человека, прибыль после релиза делится поровну" -> 4 человека, прибыль после релиза делится поровну
B10: Контент MVP | C10: =Контент_MVP -> 4 истории × 4 главы = 16 глав
B11: Релиз | C11: =Месяц_релиза_текст -> Янв 2027
B12: Активный сценарий | C12: =Сценарий -> Базовый
B13: Статус проверок модели | C13: =Статус_проверок -> Все проверки пройдены
B15: Главные результаты (активный сценарий)
B16: Выручка за 12 мес. | C16: =FIXED(KPI_выручка,0)&" ₽" -> 612,516 ₽
B17: Чистая прибыль | C17: =FIXED(KPI_ЧП,0)&" ₽ (рентабельность "&FIXED(KPI_ЧП_м*100,1)&"%)" -> 110,635 ₽ (рентабельность 18.1%)
B18: ROI на собственный капитал | C18: =FIXED(KPI_ROI*100,0)&"%" -> 55%
B19: Точка безубыточности | C19: =FIXED(BEP_MAU,0)&" MAU; EBITDA положительна с: "&BEP_месяц -> 6,236 MAU; EBITDA положительна с: Апр 2027
B20: Окупаемость вложений команды | C20: =IF(ISNUMBER(PP_docx),FIXED(PP_docx,1)&" мес.: выход в плюс в "&PP_docx_мес&" ("&ROUNDUP(PP_docx,0)&"-й месяц проекта)","за пределами 12 месяцев") -> 11.0 мес.: выход в плюс в Июл 2027 (11-й месяц проекта)
B21: Деньги на конец периода | C21: =FIXED(KPI_деньги,0)&" ₽, минимум "&FIXED(KPI_мин_деньги,0)&" ₽" -> 310,635 ₽, минимум 69,243 ₽
B23: Содержание
B24: =HYPERLINK("#'Дашборд'!A1","Дашборд") -> Дашборд | C24: Ключевые цифры и графики
B25: =HYPERLINK("#'Допущения'!A1","Допущения") -> Допущения | C25: Все вводные: меняйте только жёлтые ячейки с синими цифрами. Здесь же выбор сценария
B26: =HYPERLINK("#'Выручка'!A1","Выручка") -> Выручка | C26: Помесячная выручка: MAU, реклама interstitial и rewarded, покупки IAP
B27: =HYPERLINK("#'Расходы'!A1","Расходы") -> Расходы | C27: Операционные расходы по фазам проекта и комиссия магазина
B28: =HYPERLINK("#'Кредит'!A1","Кредит") -> Кредит | C28: График кредита: льготный период и аннуитет
B29: =HYPERLINK("#'ОПиУ'!A1","ОПиУ") -> ОПиУ | C29: Отчёт о прибылях и убытках с расчётом налога УСН
B30: =HYPERLINK("#'ДДС'!A1","ДДС") -> ДДС | C30: Движение денежных средств и остаток денег
B31: =HYPERLINK("#'Баланс'!A1","Баланс") -> Баланс | C31: Упрощённый баланс: проверка, что всё сходится
B32: =HYPERLINK("#'Показатели'!A1","Показатели") -> Показатели | C32: Точка безубыточности, окупаемость, NPV/IRR, DSCR, юнит-экономика
B33: =HYPERLINK("#'Сценарии'!A1","Сценарии") -> Сценарии | C33: Четыре сценария полной логикой + стресс-тест задержки релиза
B34: =HYPERLINK("#'Чувствительность'!A1","Чувствительность") -> Чувствительность | C34: Торнадо, сетка MAU × eCPM, стресс-тест DAU/MAU
B35: =HYPERLINK("#'Команда'!A1","Команда") -> Команда | C35: Роли, взносы и что получит каждый участник
B36: =HYPERLINK("#'Риски'!A1","Риски") -> Риски | C36: Матрица рисков docx с оценкой эффекта в модели
B37: =HYPERLINK("#'Защита'!A1","Защита") -> Защита | C37: Выводы и ответы на вопросы с живыми цифрами
B38: =HYPERLINK("#'Проверки'!A1","Проверки") -> Проверки | C38: Проверки целостности, сверка с docx и что стоит поправить
B40: Условные обозначения
B41: 1000 | C41: Ввод: можно менять
B42: 1000 | C42: Ключевое допущение, которое стоит перепроверить
B43: 1000 | C43: Формула
B44: 1000 | C44: Ссылка на другой лист
B45: -1000 | C45: Отрицательные значения красным
...

Sheet Дашборд
B2: ="Дашборд: проект "&Проект -> Дашборд: проект «Наследие»
B3: ="Сценарий: «"&Сценарий&"» | "&Статус_проверок&" | релиз: "&Месяц_релиза_текст -> Сценарий: «Базовый» | Все проверки пройдены | релиз: Янв 2027
R4: Данные для графиков (ссылки на листы модели)
B5: ВЫРУЧКА ЗА 12 МЕС. | F5: EBITDA | J5: ЧИСТАЯ ПРИБЫЛЬ | N5: ДЕНЬГИ НА КОНЕЦ ПЕРИОДА | R5: Показатель | S5: =Выручка!H$5 -> Сен 2026 | T5: =Выручка!I$5 -> Окт 2026 | U5: =Выручка!J$5 -> Ноя 2026 | V5: =Выручка!K$5 -> Дек 2026 | W5: =Выручка!L$5 -> Янв 2027 | X5: =Выручка!M$5 -> Фев 2027 | Y5: =Выручка!N$5 -> Мар 2027 | Z5: =Выручка!O$5 -> Апр 2027 | ... AD5: =Выручка!S$5 -> Авг 2027
B6: =KPI_выручка -> 612516.15 | F6: =KPI_EBITDA -> 110635.14 | J6: =KPI_ЧП -> 110635.14 | N6: =KPI_деньги -> 310635.14 | R6: Interstitial | S6: =Выручка!H19 -> 0 | T6: =Выручка!I19 -> 0 | U6: =Выручка!J19 -> 0 | V6: =Выручка!K19 -> 0 | W6: =Выручка!L19 -> 2733.75 | X6: =Выручка!M19 -> 5467.5 | Y6: =Выручка!N19 -> 9112.5 | Z6: =Выручка!O19 -> 12757.5 | ... AD6: =Выручка!S19 -> 36450
B7: ="реклама "&(FIXED((Выручка!$F$37)*100,0)&"%")&", покупки "&(FIXED((1-Выручка!$F$37)*100,0)&"%") -> реклама 59%, покупки 41% | F7: ="рентабельность "&(FIXED((KPI_EBITDA_м)*100,1)&"%") -> рентабельность 18.1% | J7: ="рентабельность "&(FIXED((KPI_ЧП_м)*100,1)&"%")&", на участника "&(FIXED(ОПиУ!$F$31*Доля_1,0))&" ₽" -> рентабельность 18.1%, на участника 27,659 ₽ | N7: ="минимум "&(FIXED(KPI_мин_деньги,0))&" ₽ ("&(KPI_мин_деньги_мес)&")" -> минимум 69,243 ₽ (Мар 2027) | R7: Rewarded | S7: =Выручка!H25 -> 0 | T7: =Выручка!I25 -> 0 | U7: =Выручка!J25 -> 0 | V7: =Выручка!K25 -> 0 | W7: =Выручка!L25 -> 4320 | X7: =Выручка!M25 -> 8748 | Y7: =Выручка!N25 -> 14940 | Z7: =Выручка!O25 -> 21420 | ... AD7: =Выручка!S25 -> 64800
R8: IAP | S8: =Выручка!H31 -> 0 | T8: =Выручка!I31 -> 0 | U8: =Выручка!J31 -> 0 | V8: =Выручка!K31 -> 0 | W8: =Выручка!L31 -> 3251.6 | X8: =Выручка!M31 -> 7163.2 | Y8: =Выручка!N31 -> 12752.8 | Z8: =Выручка!O31 -> 19353.6 | ... AD8: =Выручка!S31 -> 79120
B9: ROI НА СОБСТВЕННЫЙ КАПИТАЛ | F9: ТОЧКА БЕЗУБЫТОЧНОСТИ | J9: ОКУПАЕМОСТЬ ВЛОЖЕНИЙ | N9: ЧДД (NPV) ПРОЕКТА | R9: MAU | S9: =Выручка!H13 -> 0 | T9: =Выручка!I13 -> 0 | U9: =Выручка!J13 -> 0 | V9: =Выручка!K13 -> 0 | W9: =Выручка!L13 -> 1500 | X9: =Выручка!M13 -> 3000 | Y9: =Выручка!N13 -> 5000 | Z9: =Выручка!O13 -> 7000 | ... AD9: =Выручка!S13 -> 20000
B10: =KPI_ROI -> 0.5531757 | F10: =FIXED(BEP_MAU,0)&" MAU" -> 6,236 MAU | J10: =IF(ISNUMBER(PP_docx),FIXED(PP_docx,1)&" мес.","> 12 мес.") -> 11.0 мес. | N10: =ЧДД -> 79741.265 | R10: EBITDA | S10: =ОПиУ!H26 -> -4000 | T10: =ОПиУ!I26 -> -6000 | U10: =ОПиУ!J26 -> -16000 | V10: =ОПиУ!K26 -> -26000 | W10: =ОПиУ!L26 -> -37093.64 | X10: =ОПиУ!M26 -> -27518.28 | Y10: =ОПиУ!N26 -> -14145.12 | Z10: =ОПиУ!O26 -> 375.56 | ... AD10: =ОПиУ!S26 -> 110352
B11: ="вложено "&FIXED(Собств_капитал,0)&" ₽ собственных средств" -> вложено 200,000 ₽ собственных средств | F11: ="EBITDA ≥ 0 с: "&(BEP_месяц) -> EBITDA ≥ 0 с: Апр 2027 | J11: ="выход в плюс: "&(PP_docx_мес)&"; проект: "&(IF(ISNUMBER(PP_проект),FIXED(PP_проект,1)&" мес.","> 12 мес.")) -> выход в плюс: Июл 2027; проект: 11.0 мес. | N11: ="ВНД "&(IF(ISNUMBER(ВНД),FIXED(ВНД*100,0)&"% годовых",ВНД))&", ставка "&(FIXED((Ставка_дисконта)*100,0)&"%") -> ВНД 211% годовых, ставка 22% | R11: Чистая прибыль | S11: =ОПиУ!H31 -> -4000 | T11: =ОПиУ!I31 -> -6000 | U11: =ОПиУ!J31 -> -16000 | V11: =ОПиУ!K31 -> -26000 | W11: =ОПиУ!L31 -> -37093.64 | X11: =ОПиУ!M31 -> -27518.28 | Y11: =ОПиУ!N31 -> -14145.12 | Z11: =ОПиУ!O31 -> 375.56 | ... AD11: =ОПиУ!S31 -> 110352
R12: Чистый денежный поток | S12: =ДДС!H25 -> 196000 | T12: =ДДС!I25 -> -6000 | U12: =ДДС!J25 -> -16000 | V12: =ДДС!K25 -> -26000 | W12: =ДДС!L25 -> -37093.64 | X12: =ДДС!M25 -> -27518.28 | Y12: =ДДС!N25 -> -14145.12 | Z12: =ДДС!O25 -> 375.56 | ... AD12: =ДДС!S25 -> 110352
R13: Остаток денег | S13: =ДДС!H27 -> 196000 | T13: =ДДС!I27 -> 190000 | U13: =ДДС!J27 -> 174000 | V13: =ДДС!K27 -> 148000 | W13: =ДДС!L27 -> 110906.36 | X13: =ДДС!M27 -> 83388.08 | Y13: =ДДС!N27 -> 69242.96 | Z13: =ДДС!O27 -> 69618.52 | ... AD13: =ДДС!S27 -> 310635.14
R14: Накопленный поток проекта | S14: =Показатели!H122 -> -4000 | T14: =Показатели!I122 -> -10000 | U14: =Показатели!J122 -> -26000 | V14: =Показатели!K122 -> -52000 | W14: =Показатели!L122 -> -89093.64 | X14: =Показатели!M122 -> -116611.92 | Y14: =Показатели!N122 -> -130757.04 | Z14: =Показатели!O122 -> -130381.48 | ... AD14: =Показатели!S122 -> 110635.14
R15: Короткая подпись месяца (для осей) | S15: =CHOOSE(MONTH(Выручка!H$7),"Янв","Фев","Мар","Апр","Май","Июн","Июл","Авг","Сен","Окт","Ноя","Дек")&" "&RIGHT(YEAR(Выручка!H$7),2) -> Сен 26 | T15: =CHOOSE(MONTH(Выручка!I$7),"Янв","Фев","Мар","Апр","Май","Июн","Июл","Авг","Сен","Окт","Ноя","Дек")&" "&RIGHT(YEAR(Выручка!I$7),2) -> Окт 26 | U15: =CHOOSE(MONTH(Выручка!J$7),"Янв","Фев","Мар","Апр","Май","Июн","Июл","Авг","Сен","Окт","Ноя","Дек")&" "&RIGHT(YEAR(Выручка!J$7),2) -> Ноя 26 | V15: =CHOOSE(MONTH(Выручка!K$7),"Янв","Фев","Мар","Апр","Май","Июн","Июл","Авг","Сен","Окт","Ноя","Дек")&" "&RIGHT(YEAR(Выручка!K$7),2) -> Дек 26 | W15: =CHOOSE(MONTH(Выручка!L$7),"Янв","Фев","Мар","Апр","Май","Июн","Июл","Авг","Сен","Окт","Ноя","Дек")&" "&RIGHT(YEAR(Выручка!L$7),2) -> Янв 27 | X15: =CHOOSE(MONTH(Выручка!M$7),"Янв","Фев","Мар","Апр","Май","Июн","Июл","Авг","Сен","Окт","Ноя","Дек")&" "&RIGHT(YEAR(Выручка!M$7),2) -> Фев 27 | Y15: =CHOOSE(MONTH(Выручка!N$7),"Янв","Фев","Мар","Апр","Май","Июн","Июл","Авг","Сен","Окт","Ноя","Дек")&" "&RIGHT(YEAR(Выручка!N$7),2) -> Мар 27 | Z15: =CHOOSE(MONTH(Выручка!O$7),"Янв","Фев","Мар","Апр","Май","Июн","Июл","Авг","Сен","Окт","Ноя","Дек")&" "&RIGHT(YEAR(Выручка!O$7),2) -> Апр 27 | ... AD15: =CHOOSE(MONTH(Выручка!S$7),"Янв","Фев","Мар","Апр","Май","Июн","Июл","Авг","Сен","Окт","Ноя","Дек")&" "&RIGHT(YEAR(Выручка!S$7),2) -> Авг 27
B46: Графики строятся по блоку данных справа (столбцы R-AD); он ссылается на листы модели.

Sheet Допущения
B2: Допущения и вводные данные
B3: Меняйте только ячейки с синими цифрами на жёлтом фоне. Всё остальное считается формулами. Оранжевым выделены ключевые допущения, которые стоит перепроверить (см. лист «Проверки»).
B5: 1. Общие параметры
B6: Название проекта | E6: «Наследие» | F6: Визуальная новелла на основе фольклора народов России
B7: Дата начала проекта | D7: дата | E7: 46266 | F7: docx: период планирования сентябрь 2026 - август 2027
B8: Горизонт модели | D8: мес. | E8: 12 | F8: Модель рассчитана на 12 помесячных колонок
B9: Длительность разработки до релиза | D9: мес. | E9: 4 | F9: docx: разработка 4 мес., релиз в январе 2027
B10: Задержка релиза (стресс-тест) | D10: мес. | E10: 0 | F10: 0 = по плану. Сдвигает кривую MAU и продлевает разработку
B11: Месяц релиза (расчёт) | E11: =IF(Мес_разработки+Задержка_релиза>=12,"за горизонтом",CHOOSE(MONTH(DATE(YEAR(Дата_начала),MONTH(Дата_начала)+Мес_разработки+Задержка_релиза,1)),"Янв","Фев","Мар","Апр","Май","Июн","Июл","Авг","Сен","Окт","Ноя","Дек")&" "&YEAR(DATE(YEAR(Дата_начала),MONTH(Дата_начала)+Мес_разработки+Задержка_релиза,1))) -> Янв 2027
B12: Дней в месяце (для расчёта показов рекламы) | D12: дн. | E12: 30 | F12: docx: «пользователей × 30 дней»
B13: Контент MVP | E13: 4 истории × 4 главы = 16 глав
B15: 2. Финансирование
B16: Число участников команды | D16: чел. | E16: 4 | F16: docx: команда из 4 человек
B17: Взнос каждого участника | D17: ₽ | E17: 50000 | F17: docx: по 50 000 ₽ с участника
B18: Собственный капитал команды | D18: ₽ | E18: =Участников*Взнос_участника -> 200000 | F18: Покрывает разработку и резерв
B19: Месяц внесения капитала | D19: № мес. | E19: 1
B20: Кредит: банк
B21: Сумма кредита | D21: ₽
B22: Ставка по кредиту | D22: % годовых
B23: Срок кредита | D23: мес.
B24: Льготный период (только проценты) | D24: мес.
B25: Месяц получения кредита | D25: № мес.
B26: Итого финансирование (собственные средства) | D26: ₽ | E26: =Собств_капитал -> 200000 | F26: Заёмных средств нет
B27: Доля собственных средств | D27: % | E27: =IF(Финансирование>0,Собств_капитал/Финансирование,0) -> 1 | F27: docx: смешанная модель 50/50
B29: 3. Аудитория и монетизация
B30: DAU/MAU: доля MAU, заходящих в игру каждый день | D30: % | E30: 0.3 | F30: В docx неявно 100%: показы = MAU × 30 дней. Главное допущение модели, см. «Проверки»
B31: Interstitial: доля пользователей, видящих рекламу | D31: % | E31: 0.9 | F31: Реклама как в презентации: обязательная, видят 90% DAU (остальные: платящие). В приложении interstitial показывается при входе в главу и при выходе из истории, не чаще раза в 30 минут. Провайдеры пока не подключены, в приложении заглушки
B32: Interstitial: показов в день на пользователя | D32: шт. | E32: 1.5 | F32: 1 показ раз в 30 минут при сессии 30 минут, около 1,5 сессии в день. Реализовано в приложении заглушкой `Ads.Interstitial`
B33: Interstitial: eCPM | D33: ₽ | E33: 150 | F33: docx: eCPM = 100 ₽
B34: Rewarded: просмотров в день на смотрящего | D34: шт. | E34: 2 | F34: Ролик за награду: 3 алмаза каждые 30 минут (раздел «Награды»), +энергия в чате, спин колеса. В приложении заглушка `Ads.Rewarded`. Доля смотрящих по месяцам в п. 4
B35: Rewarded: eCPM | D35: ₽ | E35: 200 | F35: docx: eCPM = 150 ₽
B36: Комиссия магазина с IAP (алмазы и энергия) | D36: % | E36: 0.15 | F36: Установка игры из RuStore бесплатна, платных загрузок нет. Комиссия магазина 15% удерживается только с покупок внутри игры
B37: Лаг поступления выручки на счёт | D37: мес. | E37: 0 | F37: 0 = деньги приходят в месяце начисления (как в docx). Рекламные сети платят по итогам месяца
B39: 4. План по месяцам после релиза (docx, раздел 5.2)
B40: Месяц после релиза | D40: Ед. | E40: 1 | F40: 2 | G40: 3 | H40: 4 | I40: 5 | J40: 6 | K40: 7 | L40: 8 | M40: 9 | N40: 10 | O40: 11 | P40: 12
B41: Календарный месяц при текущих вводных | E41: =IF(Мес_разработки+Задержка_релиза+E$40>12,"вне горизонта",CHOOSE(MONTH(DATE(YEAR(Дата_начала),MONTH(Дата_начала)+Мес_разработки+Задержка_релиза+E$40-1,1)),"Янв","Фев","Мар","Апр","Май","Июн","Июл","Авг","Сен","Окт","Ноя","Дек")&" "&YEAR(DATE(YEAR(Дата_начала),MONTH(Дата_начала)+Мес_разработки+Задержка_релиза+E$40-1,1))) -> Янв 2027 | F41: =IF(Мес_разработки+Задержка_релиза+F$40>12,"вне горизонта",CHOOSE(MONTH(DATE(YEAR(Дата_начала),MONTH(Дата_начала)+Мес_разработки+Задержка_релиза+F$40-1,1)),"Янв","Фев","Мар","Апр","Май","Июн","Июл","Авг","Сен","Окт","Ноя","Дек")&" "&YEAR(DATE(YEAR(Дата_начала),MONTH(Дата_начала)+Мес_разработки+Задержка_релиза+F$40-1,1))) -> Фев 2027 | G41: =IF(Мес_разработки+Задержка_релиза+G$40>12,"вне горизонта",CHOOSE(MONTH(DATE(YEAR(Дата_начала),MONTH(Дата_начала)+Мес_разработки+Задержка_релиза+G$40-1,1)),"Янв","Фев","Мар","Апр","Май","Июн","Июл","Авг","Сен","Окт","Ноя","Дек")&" "&YEAR(DATE(YEAR(Дата_начала),MONTH(Дата_начала)+Мес_разработки+Задержка_релиза+G$40-1,1))) -> Мар 2027 | H41: =IF(Мес_разработки+Задержка_релиза+H$40>12,"вне горизонта",CHOOSE(MONTH(DATE(YEAR(Дата_начала),MONTH(Дата_начала)+Мес_разработки+Задержка_релиза+H$40-1,1)),"Янв","Фев","Мар","Апр","Май","Июн","Июл","Авг","Сен","Окт","Ноя","Дек")&" "&YEAR(DATE(YEAR(Дата_начала),MONTH(Дата_начала)+Мес_разработки+Задержка_релиза+H$40-1,1))) -> Апр 2027 | I41: =IF(Мес_разработки+Задержка_релиза+I$40>12,"вне горизонта",CHOOSE(MONTH(DATE(YEAR(Дата_начала),MONTH(Дата_начала)+Мес_разработки+Задержка_релиза+I$40-1,1)),"Янв","Фев","Мар","Апр","Май","Июн","Июл","Авг","Сен","Окт","Ноя","Дек")&" "&YEAR(DATE(YEAR(Дата_начала),MONTH(Дата_начала)+Мес_разработки+Задержка_релиза+I$40-1,1))) -> Май 2027 | J41: =IF(Мес_разработки+Задержка_релиза+J$40>12,"вне горизонта",CHOOSE(MONTH(DATE(YEAR(Дата_начала),MONTH(Дата_начала)+Мес_разработки+Задержка_релиза+J$40-1,1)),"Янв","Фев","Мар","Апр","Май","Июн","Июл","Авг","Сен","Окт","Ноя","Дек")&" "&YEAR(DATE(YEAR(Дата_начала),MONTH(Дата_начала)+Мес_разработки+Задержка_релиза+J$40-1,1))) -> Июн 2027 | K41: =IF(Мес_разработки+Задержка_релиза+K$40>12,"вне горизонта",CHOOSE(MONTH(DATE(YEAR(Дата_начала),MONTH(Дата_начала)+Мес_разработки+Задержка_релиза+K$40-1,1)),"Янв","Фев","Мар","Апр","Май","Июн","Июл","Авг","Сен","Окт","Ноя","Дек")&" "&YEAR(DATE(YEAR(Дата_начала),MONTH(Дата_начала)+Мес_разработки+Задержка_релиза+K$40-1,1))) -> Июл 2027 | L41: =IF(Мес_разработки+Задержка_релиза+L$40>12,"вне горизонта",CHOOSE(MONTH(DATE(YEAR(Дата_начала),MONTH(Дата_начала)+Мес_разработки+Задержка_релиза+L$40-1,1)),"Янв","Фев","Мар","Апр","Май","Июн","Июл","Авг","Сен","Окт","Ноя","Дек")&" "&YEAR(DATE(YEAR(Дата_начала),MONTH(Дата_начала)+Мес_разработки+Задержка_релиза+L$40-1,1))) -> Авг 2027 | ... P41: =IF(Мес_разработки+Задержка_релиза+P$40>12,"вне горизонта",CHOOSE(MONTH(DATE(YEAR(Дата_начала),MONTH(Дата_начала)+Мес_разработки+Задержка_релиза+P$40-1,1)),"Янв","Фев","Мар","Апр","Май","Июн","Июл","Авг","Сен","Окт","Ноя","Дек")&" "&YEAR(DATE(YEAR(Дата_начала),MONTH(Дата_начала)+Мес_разработки+Задержка_релиза+P$40-1,1))) -> вне горизонта
B42: MAU (активные пользователи в месяц) | D42: чел. | E42: 1500 | F42: 3000 | G42: 5000 | H42: 7000 | I42: 9000 | J42: 12000 | K42: 16000 | L42: 20000 | M42: 25000 | N42: 25000 | O42: 25000 | P42: 25000
B43: Rewarded: доля смотрящих рекламу | D43: % | E43: 0.8 | F43: 0.81 | G43: 0.83 | H43: 0.85 | I43: 0.86 | J43: 0.87 | K43: 0.88 | L43: 0.9 | M43: 0.95 | N43: 0.95 | O43: 0.95 | P43: 0.95
B44: IAP: конверсия в плательщиков | D44: % | E44: 0.007 | F44: 0.0072 | G44: 0.0075 | H44: 0.008 | I44: 0.0085 | J44: 0.009 | K44: 0.0095 | L44: 0.01 | M44: 0.01 | N44: 0.01 | O44: 0.01 | P44: 0.01
B45: IAP: средний чек (ARPPU) | D45: ₽ | E45: 199 | F45: 229 | G45: 239 | H45: 249 | I45: 259 | J45: 279 | K45: 289 | L45: 299 | M45: 329 | N45: 349 | O45: 359 | P45: 359
...

Sheet Выручка
B2: Выручка: помесячный расчёт
B3: ₽. Логика docx, раздел 5: реклама interstitial + rewarded + внутриигровые покупки (IAP). Сценарные множители берутся из «Допущений», п. 9.
B5: Показатель | C5: Ед. | D5: ="Разработка"&CHAR(10)&"("&Дев_мес&" мес.)" -> Разработка (4 мес.) | E5: ="Операционка"&CHAR(10)&"("&Опер_мес&" мес.)" -> Операционка (8 мес.) | F5: ="Итого"&CHAR(10)&"12 мес." -> Итого 12 мес. | H5: =CHOOSE(MONTH(H7),"Янв","Фев","Мар","Апр","Май","Июн","Июл","Авг","Сен","Окт","Ноя","Дек")&" "&YEAR(H7) -> Сен 2026 | I5: =CHOOSE(MONTH(I7),"Янв","Фев","Мар","Апр","Май","Июн","Июл","Авг","Сен","Окт","Ноя","Дек")&" "&YEAR(I7) -> Окт 2026 | J5: =CHOOSE(MONTH(J7),"Янв","Фев","Мар","Апр","Май","Июн","Июл","Авг","Сен","Окт","Ноя","Дек")&" "&YEAR(J7) -> Ноя 2026 | K5: =CHOOSE(MONTH(K7),"Янв","Фев","Мар","Апр","Май","Июн","Июл","Авг","Сен","Окт","Ноя","Дек")&" "&YEAR(K7) -> Дек 2026 | L5: =CHOOSE(MONTH(L7),"Янв","Фев","Мар","Апр","Май","Июн","Июл","Авг","Сен","Окт","Ноя","Дек")&" "&YEAR(L7) -> Янв 2027 | M5: =CHOOSE(MONTH(M7),"Янв","Фев","Мар","Апр","Май","Июн","Июл","Авг","Сен","Окт","Ноя","Дек")&" "&YEAR(M7) -> Фев 2027 | N5: =CHOOSE(MONTH(N7),"Янв","Фев","Мар","Апр","Май","Июн","Июл","Авг","Сен","Окт","Ноя","Дек")&" "&YEAR(N7) -> Мар 2027 | O5: =CHOOSE(MONTH(O7),"Янв","Фев","Мар","Апр","Май","Июн","Июл","Авг","Сен","Окт","Ноя","Дек")&" "&YEAR(O7) -> Апр 2027 | ... S5: =CHOOSE(MONTH(S7),"Янв","Фев","Мар","Апр","Май","Июн","Июл","Авг","Сен","Окт","Ноя","Дек")&" "&YEAR(S7) -> Авг 2027
B6: № месяца проекта | H6: 1 | I6: =H6+1 -> 2 | J6: =I6+1 -> 3 | K6: =J6+1 -> 4 | L6: =K6+1 -> 5 | M6: =L6+1 -> 6 | N6: =M6+1 -> 7 | O6: =N6+1 -> 8 | P6: =O6+1 -> 9 | ... S6: =R6+1 -> 12
B7: Дата (начало месяца) | H7: =DATE(YEAR(Дата_начала),MONTH(Дата_начала)+H6-1,1) -> 46266 | I7: =DATE(YEAR(Дата_начала),MONTH(Дата_начала)+I6-1,1) -> 46296 | J7: =DATE(YEAR(Дата_начала),MONTH(Дата_начала)+J6-1,1) -> 46327 | K7: =DATE(YEAR(Дата_начала),MONTH(Дата_начала)+K6-1,1) -> 46357 | L7: =DATE(YEAR(Дата_начала),MONTH(Дата_начала)+L6-1,1) -> 46388 | M7: =DATE(YEAR(Дата_начала),MONTH(Дата_начала)+M6-1,1) -> 46419 | N7: =DATE(YEAR(Дата_начала),MONTH(Дата_начала)+N6-1,1) -> 46447 | O7: =DATE(YEAR(Дата_начала),MONTH(Дата_начала)+O6-1,1) -> 46478 | ... S7: =DATE(YEAR(Дата_начала),MONTH(Дата_начала)+S6-1,1) -> 46600
B8: Фаза | D8: =COUNTIF($H$8:$S$8,"Разработка") -> 4 | E8: =COUNTIF($H$8:$S$8,"Операционка") -> 8 | F8: =D8+E8 -> 12 | H8: =IF(H6<=Мес_разработки+Задержка_релиза,"Разработка","Операционка") -> Разработка | I8: =IF(I6<=Мес_разработки+Задержка_релиза,"Разработка","Операционка") -> Разработка | J8: =IF(J6<=Мес_разработки+Задержка_релиза,"Разработка","Операционка") -> Разработка | K8: =IF(K6<=Мес_разработки+Задержка_релиза,"Разработка","Операционка") -> Разработка | L8: =IF(L6<=Мес_разработки+Задержка_релиза,"Разработка","Операционка") -> Операционка | M8: =IF(M6<=Мес_разработки+Задержка_релиза,"Разработка","Операционка") -> Операционка | N8: =IF(N6<=Мес_разработки+Задержка_релиза,"Разработка","Операционка") -> Операционка | O8: =IF(O6<=Мес_разработки+Задержка_релиза,"Разработка","Операционка") -> Операционка | ... S8: =IF(S6<=Мес_разработки+Задержка_релиза,"Разработка","Операционка") -> Операционка
B9: Месяцев после релиза | H9: =MAX(0,H6-Мес_разработки-Задержка_релиза) -> 0 | I9: =MAX(0,I6-Мес_разработки-Задержка_релиза) -> 0 | J9: =MAX(0,J6-Мес_разработки-Задержка_релиза) -> 0 | K9: =MAX(0,K6-Мес_разработки-Задержка_релиза) -> 0 | L9: =MAX(0,L6-Мес_разработки-Задержка_релиза) -> 1 | M9: =MAX(0,M6-Мес_разработки-Задержка_релиза) -> 2 | N9: =MAX(0,N6-Мес_разработки-Задержка_релиза) -> 3 | O9: =MAX(0,O6-Мес_разработки-Задержка_релиза) -> 4 | ... S9: =MAX(0,S6-Мес_разработки-Задержка_релиза) -> 8
B11: Аудитория
B12: MAU по плану (до сценарного множителя) | C12: чел. | D12: =INDEX($H$12:$S$12,1,Дев_мес) -> 0 | E12: =IF(Опер_мес>0,S12,"") -> 20000 | F12: =S12 -> 20000 | H12: =IF(H$9>0,INDEX(План_MAU,1,H$9),0) -> 0 | I12: =IF(I$9>0,INDEX(План_MAU,1,I$9),0) -> 0 | J12: =IF(J$9>0,INDEX(План_MAU,1,J$9),0) -> 0 | K12: =IF(K$9>0,INDEX(План_MAU,1,K$9),0) -> 0 | L12: =IF(L$9>0,INDEX(План_MAU,1,L$9),0) -> 1500 | M12: =IF(M$9>0,INDEX(План_MAU,1,M$9),0) -> 3000 | N12: =IF(N$9>0,INDEX(План_MAU,1,N$9),0) -> 5000 | O12: =IF(O$9>0,INDEX(План_MAU,1,O$9),0) -> 7000 | ... S12: =IF(S$9>0,INDEX(План_MAU,1,S$9),0) -> 20000
B13: MAU (активный сценарий) | C13: чел. | D13: =INDEX($H$13:$S$13,1,Дев_мес) -> 0 | E13: =IF(Опер_мес>0,S13,"") -> 20000 | F13: =S13 -> 20000 | H13: =H12*Сц_MAU -> 0 | I13: =I12*Сц_MAU -> 0 | J13: =J12*Сц_MAU -> 0 | K13: =K12*Сц_MAU -> 0 | L13: =L12*Сц_MAU -> 1500 | M13: =M12*Сц_MAU -> 3000 | N13: =N12*Сц_MAU -> 5000 | O13: =O12*Сц_MAU -> 7000 | ... S13: =S12*Сц_MAU -> 20000
B14: DAU: заходят в игру в среднем за день | C14: чел. | D14: =INDEX($H$14:$S$14,1,Дев_мес) -> 0 | E14: =IF(Опер_мес>0,S14,"") -> 6000 | F14: =S14 -> 6000 | H14: =H13*DAU_MAU -> 0 | I14: =I13*DAU_MAU -> 0 | J14: =J13*DAU_MAU -> 0 | K14: =K13*DAU_MAU -> 0 | L14: =L13*DAU_MAU -> 450 | M14: =M13*DAU_MAU -> 900 | N14: =N13*DAU_MAU -> 1500 | O14: =O13*DAU_MAU -> 2100 | ... S14: =S13*DAU_MAU -> 6000
B16: Interstitial (обязательная реклама)
B17: Показов в месяц | C17: шт. | D17: =SUMIF($H$8:$S$8,"Разработка",$H$17:$S$17) -> 0 | E17: =SUMIF($H$8:$S$8,"Операционка",$H$17:$S$17) -> 893025 | F17: =SUM($H$17:$S$17) -> 893025 | H17: =H14*Int_доля*Int_показов*Дней_в_месяце -> 0 | I17: =I14*Int_доля*Int_показов*Дней_в_месяце -> 0 | J17: =J14*Int_доля*Int_показов*Дней_в_месяце -> 0 | K17: =K14*Int_доля*Int_показов*Дней_в_месяце -> 0 | L17: =L14*Int_доля*Int_показов*Дней_в_месяце -> 18225 | M17: =M14*Int_доля*Int_показов*Дней_в_месяце -> 36450 | N17: =N14*Int_доля*Int_показов*Дней_в_месяце -> 60750 | O17: =O14*Int_доля*Int_показов*Дней_в_месяце -> 85050 | ... S17: =S14*Int_доля*Int_показов*Дней_в_месяце -> 243000
B18: eCPM (доход за 1000 показов) | C18: ₽ | E18: =IFERROR(AVERAGEIF($H$8:$S$8,"Операционка",$H$18:$S$18),0) -> 150 | F18: =IFERROR(AVERAGEIF($H$8:$S$8,"Операционка",$H$18:$S$18),0) -> 150 | H18: =IF(H$9>0,Int_eCPM*Сц_eCPM,0) -> 0 | I18: =IF(I$9>0,Int_eCPM*Сц_eCPM,0) -> 0 | J18: =IF(J$9>0,Int_eCPM*Сц_eCPM,0) -> 0 | K18: =IF(K$9>0,Int_eCPM*Сц_eCPM,0) -> 0 | L18: =IF(L$9>0,Int_eCPM*Сц_eCPM,0) -> 150 | M18: =IF(M$9>0,Int_eCPM*Сц_eCPM,0) -> 150 | N18: =IF(N$9>0,Int_eCPM*Сц_eCPM,0) -> 150 | O18: =IF(O$9>0,Int_eCPM*Сц_eCPM,0) -> 150 | ... S18: =IF(S$9>0,Int_eCPM*Сц_eCPM,0) -> 150
B19: Доход от Interstitial | C19: ₽ | D19: =SUMIF($H$8:$S$8,"Разработка",$H$19:$S$19) -> 0 | E19: =SUMIF($H$8:$S$8,"Операционка",$H$19:$S$19) -> 133953.75 | F19: =SUM($H$19:$S$19) -> 133953.75 | H19: =H17*H18/1000 -> 0 | I19: =I17*I18/1000 -> 0 | J19: =J17*J18/1000 -> 0 | K19: =K17*K18/1000 -> 0 | L19: =L17*L18/1000 -> 2733.75 | M19: =M17*M18/1000 -> 5467.5 | N19: =N17*N18/1000 -> 9112.5 | O19: =O17*O18/1000 -> 12757.5 | ... S19: =S17*S18/1000 -> 36450
B21: Rewarded (реклама за вознаграждение)
B22: Доля смотрящих rewarded | C22: % | E22: =IFERROR(AVERAGEIF($H$8:$S$8,"Операционка",$H$22:$S$22),0) -> 0.85 | F22: =IFERROR(AVERAGEIF($H$8:$S$8,"Операционка",$H$22:$S$22),0) -> 0.85 | H22: =IF(H$9>0,INDEX(План_rew_доля,1,H$9),0) -> 0 | I22: =IF(I$9>0,INDEX(План_rew_доля,1,I$9),0) -> 0 | J22: =IF(J$9>0,INDEX(План_rew_доля,1,J$9),0) -> 0 | K22: =IF(K$9>0,INDEX(План_rew_доля,1,K$9),0) -> 0 | L22: =IF(L$9>0,INDEX(План_rew_доля,1,L$9),0) -> 0.8 | M22: =IF(M$9>0,INDEX(План_rew_доля,1,M$9),0) -> 0.81 | N22: =IF(N$9>0,INDEX(План_rew_доля,1,N$9),0) -> 0.83 | O22: =IF(O$9>0,INDEX(План_rew_доля,1,O$9),0) -> 0.85 | ... S22: =IF(S$9>0,INDEX(План_rew_доля,1,S$9),0) -> 0.9
B23: Просмотров в месяц | C23: шт. | D23: =SUMIF($H$8:$S$8,"Разработка",$H$23:$S$23) -> 0 | E23: =SUMIF($H$8:$S$8,"Операционка",$H$23:$S$23) -> 1151820 | F23: =SUM($H$23:$S$23) -> 1151820 | H23: =H14*H22*Rew_просмотров*Дней_в_месяце -> 0 | I23: =I14*I22*Rew_просмотров*Дней_в_месяце -> 0 | J23: =J14*J22*Rew_просмотров*Дней_в_месяце -> 0 | K23: =K14*K22*Rew_просмотров*Дней_в_месяце -> 0 | L23: =L14*L22*Rew_просмотров*Дней_в_месяце -> 21600 | M23: =M14*M22*Rew_просмотров*Дней_в_месяце -> 43740 | N23: =N14*N22*Rew_просмотров*Дней_в_месяце -> 74700 | O23: =O14*O22*Rew_просмотров*Дней_в_месяце -> 107100 | ... S23: =S14*S22*Rew_просмотров*Дней_в_месяце -> 324000
B24: eCPM (доход за 1000 просмотров) | C24: ₽ | E24: =IFERROR(AVERAGEIF($H$8:$S$8,"Операционка",$H$24:$S$24),0) -> 200 | F24: =IFERROR(AVERAGEIF($H$8:$S$8,"Операционка",$H$24:$S$24),0) -> 200 | H24: =IF(H$9>0,Rew_eCPM*Сц_eCPM,0) -> 0 | I24: =IF(I$9>0,Rew_eCPM*Сц_eCPM,0) -> 0 | J24: =IF(J$9>0,Rew_eCPM*Сц_eCPM,0) -> 0 | K24: =IF(K$9>0,Rew_eCPM*Сц_eCPM,0) -> 0 | L24: =IF(L$9>0,Rew_eCPM*Сц_eCPM,0) -> 200 | M24: =IF(M$9>0,Rew_eCPM*Сц_eCPM,0) -> 200 | N24: =IF(N$9>0,Rew_eCPM*Сц_eCPM,0) -> 200 | O24: =IF(O$9>0,Rew_eCPM*Сц_eCPM,0) -> 200 | ... S24: =IF(S$9>0,Rew_eCPM*Сц_eCPM,0) -> 200
B25: Доход от Rewarded | C25: ₽ | D25: =SUMIF($H$8:$S$8,"Разработка",$H$25:$S$25) -> 0 | E25: =SUMIF($H$8:$S$8,"Операционка",$H$25:$S$25) -> 230364 | F25: =SUM($H$25:$S$25) -> 230364 | H25: =H23*H24/1000 -> 0 | I25: =I23*I24/1000 -> 0 | J25: =J23*J24/1000 -> 0 | K25: =K23*K24/1000 -> 0 | L25: =L23*L24/1000 -> 4320 | M25: =M23*M24/1000 -> 8748 | N25: =N23*N24/1000 -> 14940 | O25: =O23*O24/1000 -> 21420 | ... S25: =S23*S24/1000 -> 64800
B27: IAP (внутриигровые покупки)
B28: Конверсия в плательщиков | C28: % | E28: =IFERROR(AVERAGEIF($H$8:$S$8,"Операционка",$H$28:$S$28),0) -> 0.0083375 | F28: =IFERROR(AVERAGEIF($H$8:$S$8,"Операционка",$H$28:$S$28),0) -> 0.0083375 | H28: =IF(H$9>0,INDEX(План_конв,1,H$9)*Сц_конв,0) -> 0 | I28: =IF(I$9>0,INDEX(План_конв,1,I$9)*Сц_конв,0) -> 0 | J28: =IF(J$9>0,INDEX(План_конв,1,J$9)*Сц_конв,0) -> 0 | K28: =IF(K$9>0,INDEX(План_конв,1,K$9)*Сц_конв,0) -> 0 | L28: =IF(L$9>0,INDEX(План_конв,1,L$9)*Сц_конв,0) -> 0.007 | M28: =IF(M$9>0,INDEX(План_конв,1,M$9)*Сц_конв,0) -> 0.0072 | N28: =IF(N$9>0,INDEX(План_конв,1,N$9)*Сц_конв,0) -> 0.0075 | O28: =IF(O$9>0,INDEX(План_конв,1,O$9)*Сц_конв,0) -> 0.008 | ... S28: =IF(S$9>0,INDEX(План_конв,1,S$9)*Сц_конв,0) -> 0.01
B29: Плательщиков (округлено до целых, как в docx) | C29: чел. | D29: =SUMIF($H$8:$S$8,"Разработка",$H$29:$S$29) -> 0 | E29: =SUMIF($H$8:$S$8,"Операционка",$H$29:$S$29) -> 664 | F29: =SUM($H$29:$S$29) -> 664 | H29: =ROUND(H13*H28,0) -> 0 | I29: =ROUND(I13*I28,0) -> 0 | J29: =ROUND(J13*J28,0) -> 0 | K29: =ROUND(K13*K28,0) -> 0 | L29: =ROUND(L13*L28,0) -> 11 | M29: =ROUND(M13*M28,0) -> 22 | N29: =ROUND(N13*N28,0) -> 38 | O29: =ROUND(O13*O28,0) -> 56 | ... S29: =ROUND(S13*S28,0) -> 200
B30: Средний чек (ARPPU): алмазы + энергия | C30: ₽ | E30: =IFERROR(AVERAGEIF($H$8:$S$8,"Операционка",$H$30:$S$30),0) -> 351.85 | F30: =IFERROR(AVERAGEIF($H$8:$S$8,"Операционка",$H$30:$S$30),0) -> 351.85 | H30: =IF(H$9>0,INDEX(План_ARPPU,1,H$9),0)+IF(H$9>0,Энергия!$D$30,0) -> 0 | I30: =IF(I$9>0,INDEX(План_ARPPU,1,I$9),0)+IF(I$9>0,Энергия!$D$30,0) -> 0 | J30: =IF(J$9>0,INDEX(План_ARPPU,1,J$9),0)+IF(J$9>0,Энергия!$D$30,0) -> 0 | K30: =IF(K$9>0,INDEX(План_ARPPU,1,K$9),0)+IF(K$9>0,Энергия!$D$30,0) -> 0 | L30: =IF(L$9>0,INDEX(План_ARPPU,1,L$9),0)+IF(L$9>0,Энергия!$D$30,0) -> 295.6 | M30: =IF(M$9>0,INDEX(План_ARPPU,1,M$9),0)+IF(M$9>0,Энергия!$D$30,0) -> 325.6 | N30: =IF(N$9>0,INDEX(План_ARPPU,1,N$9),0)+IF(N$9>0,Энергия!$D$30,0) -> 335.6 | O30: =IF(O$9>0,INDEX(План_ARPPU,1,O$9),0)+IF(O$9>0,Энергия!$D$30,0) -> 345.6 | ... S30: =IF(S$9>0,INDEX(План_ARPPU,1,S$9),0)+IF(S$9>0,Энергия!$D$30,0) -> 395.6
B31: Доход от IAP (алмазы и энергия) | C31: ₽ | D31: =SUMIF($H$8:$S$8,"Разработка",$H$31:$S$31) -> 0 | E31: =SUMIF($H$8:$S$8,"Операционка",$H$31:$S$31) -> 248198.4 | F31: =SUM($H$31:$S$31) -> 248198.4 | H31: =H29*H30 -> 0 | I31: =I29*I30 -> 0 | J31: =J29*J30 -> 0 | K31: =K29*K30 -> 0 | L31: =L29*L30 -> 3251.6 | M31: =M29*M30 -> 7163.2 | N31: =N29*N30 -> 12752.8 | O31: =O29*O30 -> 19353.6 | ... S31: =S29*S30 -> 79120
B33: Итого
B34: Доход от рекламы | C34: ₽ | D34: =SUMIF($H$8:$S$8,"Разработка",$H$34:$S$34) -> 0 | E34: =SUMIF($H$8:$S$8,"Операционка",$H$34:$S$34) -> 364317.75 | F34: =SUM($H$34:$S$34) -> 364317.75 | H34: =H19+H25 -> 0 | I34: =I19+I25 -> 0 | J34: =J19+J25 -> 0 | K34: =K19+K25 -> 0 | L34: =L19+L25 -> 7053.75 | M34: =M19+M25 -> 14215.5 | N34: =N19+N25 -> 24052.5 | O34: =O19+O25 -> 34177.5 | ... S34: =S19+S25 -> 101250
B35: Доход от IAP (алмазы и энергия) | C35: ₽ | D35: =SUMIF($H$8:$S$8,"Разработка",$H$35:$S$35) -> 0 | E35: =SUMIF($H$8:$S$8,"Операционка",$H$35:$S$35) -> 248198.4 | F35: =SUM($H$35:$S$35) -> 248198.4 | H35: =H31 -> 0 | I35: =I31 -> 0 | J35: =J31 -> 0 | K35: =K31 -> 0 | L35: =L31 -> 3251.6 | M35: =M31 -> 7163.2 | N35: =N31 -> 12752.8 | O35: =O31 -> 19353.6 | ... S35: =S31 -> 79120
B36: ИТОГО ВЫРУЧКА | C36: ₽ | D36: =SUMIF($H$8:$S$8,"Разработка",$H$36:$S$36) -> 0 | E36: =SUMIF($H$8:$S$8,"Операционка",$H$36:$S$36) -> 612516.15 | F36: =SUM($H$36:$S$36) -> 612516.15 | H36: =H34+H35 -> 0 | I36: =I34+I35 -> 0 | J36: =J34+J35 -> 0 | K36: =K34+K35 -> 0 | L36: =L34+L35 -> 10305.35 | M36: =M34+M35 -> 21378.7 | N36: =N34+N35 -> 36805.3 | O36: =O34+O35 -> 53531.1 | ... S36: =S34+S35 -> 180370
B37: Доля рекламы в выручке | C37: % | D37: =IF(D36<>0,D34/D36,0) -> 0 | E37: =IF(E36<>0,E34/E36,0) -> 0.59478881 | F37: =IF(F36<>0,F34/F36,0) -> 0.59478881 | H37: =IF(H36>0,H34/H36,0) -> 0 | I37: =IF(I36>0,I34/I36,0) -> 0 | J37: =IF(J36>0,J34/J36,0) -> 0 | K37: =IF(K36>0,K34/K36,0) -> 0 | L37: =IF(L36>0,L34/L36,0) -> 0.68447457 | M37: =IF(M36>0,M34/M36,0) -> 0.66493753 | N37: =IF(N36>0,N34/N36,0) -> 0.65350642 | O37: =IF(O36>0,O34/O36,0) -> 0.63846063 | ... S37: =IF(S36>0,S34/S36,0) -> 0.56134612
B38: ARPU: выручка на 1 MAU в месяц | C38: ₽ | E38: =IFERROR(E36/SUMIF($H$8:$S$8,"Операционка",$H$13:$S$13),0) -> 8.3335531 | F38: =IFERROR(F36/SUM($H$13:$S$13),0) -> 8.3335531 | H38: =IF(H13>0,H36/H13,0) -> 0 | I38: =IF(I13>0,I36/I13,0) -> 0 | J38: =IF(J13>0,J36/J13,0) -> 0 | K38: =IF(K13>0,K36/K13,0) -> 0 | L38: =IF(L13>0,L36/L13,0) -> 6.8702333 | M38: =IF(M13>0,M36/M13,0) -> 7.1262333 | N38: =IF(N13>0,N36/N13,0) -> 7.36106 | O38: =IF(O13>0,O36/O13,0) -> 7.6473 | ... S38: =IF(S13>0,S36/S13,0) -> 9.0185
B40: Удельные показатели базового плана (без сценарных множителей; для листов «Сценарии» и «Чувствительность»)
B41: Interstitial на 1 MAU (по плану) | C41: ₽ | E41: =IFERROR(AVERAGEIF($H$8:$S$8,"Операционка",$H$41:$S$41),0) -> 1.8225 | F41: =IFERROR(AVERAGEIF($H$8:$S$8,"Операционка",$H$41:$S$41),0) -> 1.8225 | H41: =IF(H$9>0,DAU_MAU*Int_доля*Int_показов*Дней_в_месяце*Int_eCPM/1000,0) -> 0 | I41: =IF(I$9>0,DAU_MAU*Int_доля*Int_показов*Дней_в_месяце*Int_eCPM/1000,0) -> 0 | J41: =IF(J$9>0,DAU_MAU*Int_доля*Int_показов*Дней_в_месяце*Int_eCPM/1000,0) -> 0 | K41: =IF(K$9>0,DAU_MAU*Int_доля*Int_показов*Дней_в_месяце*Int_eCPM/1000,0) -> 0 | L41: =IF(L$9>0,DAU_MAU*Int_доля*Int_показов*Дней_в_месяце*Int_eCPM/1000,0) -> 1.8225 | M41: =IF(M$9>0,DAU_MAU*Int_доля*Int_показов*Дней_в_месяце*Int_eCPM/1000,0) -> 1.8225 | N41: =IF(N$9>0,DAU_MAU*Int_доля*Int_показов*Дней_в_месяце*Int_eCPM/1000,0) -> 1.8225 | O41: =IF(O$9>0,DAU_MAU*Int_доля*Int_показов*Дней_в_месяце*Int_eCPM/1000,0) -> 1.8225 | ... S41: =IF(S$9>0,DAU_MAU*Int_доля*Int_показов*Дней_в_месяце*Int_eCPM/1000,0) -> 1.8225
B42: Rewarded на 1 MAU (по плану) | C42: ₽ | E42: =IFERROR(AVERAGEIF($H$8:$S$8,"Операционка",$H$42:$S$42),0) -> 3.06 | F42: =IFERROR(AVERAGEIF($H$8:$S$8,"Операционка",$H$42:$S$42),0) -> 3.06 | H42: =IF(H$9>0,DAU_MAU*H22*Rew_просмотров*Дней_в_месяце*Rew_eCPM/1000,0) -> 0 | I42: =IF(I$9>0,DAU_MAU*I22*Rew_просмотров*Дней_в_месяце*Rew_eCPM/1000,0) -> 0 | J42: =IF(J$9>0,DAU_MAU*J22*Rew_просмотров*Дней_в_месяце*Rew_eCPM/1000,0) -> 0 | K42: =IF(K$9>0,DAU_MAU*K22*Rew_просмотров*Дней_в_месяце*Rew_eCPM/1000,0) -> 0 | L42: =IF(L$9>0,DAU_MAU*L22*Rew_просмотров*Дней_в_месяце*Rew_eCPM/1000,0) -> 2.88 | M42: =IF(M$9>0,DAU_MAU*M22*Rew_просмотров*Дней_в_месяце*Rew_eCPM/1000,0) -> 2.916 | N42: =IF(N$9>0,DAU_MAU*N22*Rew_просмотров*Дней_в_месяце*Rew_eCPM/1000,0) -> 2.988 | O42: =IF(O$9>0,DAU_MAU*O22*Rew_просмотров*Дней_в_месяце*Rew_eCPM/1000,0) -> 3.06 | ... S42: =IF(S$9>0,DAU_MAU*S22*Rew_просмотров*Дней_в_месяце*Rew_eCPM/1000,0) -> 3.24
B43: Конверсия IAP (по плану) | C43: % | E43: =IFERROR(AVERAGEIF($H$8:$S$8,"Операционка",$H$43:$S$43),0) -> 0.0083375 | F43: =IFERROR(AVERAGEIF($H$8:$S$8,"Операционка",$H$43:$S$43),0) -> 0.0083375 | H43: =IF(H$9>0,INDEX(План_конв,1,H$9),0) -> 0 | I43: =IF(I$9>0,INDEX(План_конв,1,I$9),0) -> 0 | J43: =IF(J$9>0,INDEX(План_конв,1,J$9),0) -> 0 | K43: =IF(K$9>0,INDEX(План_конв,1,K$9),0) -> 0 | L43: =IF(L$9>0,INDEX(План_конв,1,L$9),0) -> 0.007 | M43: =IF(M$9>0,INDEX(План_конв,1,M$9),0) -> 0.0072 | N43: =IF(N$9>0,INDEX(План_конв,1,N$9),0) -> 0.0075 | O43: =IF(O$9>0,INDEX(План_конв,1,O$9),0) -> 0.008 | ... S43: =IF(S$9>0,INDEX(План_конв,1,S$9),0) -> 0.01

Sheet Энергия
B2: Энергия и ИИ-чат: экономика
B3: ₽. Энергия = токены ИИ: 1 сообщение герою = 1 энергия, со 2-й главы каждой истории глава тоже тратит энергию. Продажа энергии идёт в средний чек IAP (лист «Выручка», строка 30), затраты на токены идут в «Затраты на ИИ-сервисы» (лист «Расходы», строка 12).
B5: Показатель | C5: Ед. | D5: Значение / Разработка | E5: Операционка | F5: Итого 12 мес. | H5: =Выручка!H$5 -> Сен 2026 | I5: =Выручка!I$5 -> Окт 2026 | J5: =Выручка!J$5 -> Ноя 2026 | K5: =Выручка!K$5 -> Дек 2026 | L5: =Выручка!L$5 -> Янв 2027 | M5: =Выручка!M$5 -> Фев 2027 | N5: =Выручка!N$5 -> Мар 2027 | O5: =Выручка!O$5 -> Апр 2027 | ... S5: =Выручка!S$5 -> Авг 2027
B6: № месяца проекта | H6: =Выручка!H$6 -> 1 | I6: =Выручка!I$6 -> 2 | J6: =Выручка!J$6 -> 3 | K6: =Выручка!K$6 -> 4 | L6: =Выручка!L$6 -> 5 | M6: =Выручка!M$6 -> 6 | N6: =Выручка!N$6 -> 7 | O6: =Выручка!O$6 -> 8 | ... S6: =Выручка!S$6 -> 12
B7: Дата (начало месяца) | H7: =Выручка!H$7 -> 46266 | I7: =Выручка!I$7 -> 46296 | J7: =Выручка!J$7 -> 46327 | K7: =Выручка!K$7 -> 46357 | L7: =Выручка!L$7 -> 46388 | M7: =Выручка!M$7 -> 46419 | N7: =Выручка!N$7 -> 46447 | O7: =Выручка!O$7 -> 46478 | ... S7: =Выручка!S$7 -> 46600
B8: Фаза | H8: =Выручка!H$8 -> Разработка | I8: =Выручка!I$8 -> Разработка | J8: =Выручка!J$8 -> Разработка | K8: =Выручка!K$8 -> Разработка | L8: =Выручка!L$8 -> Операционка | M8: =Выручка!M$8 -> Операционка | N8: =Выручка!N$8 -> Операционка | O8: =Выручка!O$8 -> Операционка | ... S8: =Выручка!S$8 -> Операционка
B9: Месяцев после релиза | H9: =Выручка!H$9 -> 0 | I9: =Выручка!I$9 -> 0 | J9: =Выручка!J$9 -> 0 | K9: =Выручка!K$9 -> 0 | L9: =Выручка!L$9 -> 1 | M9: =Выручка!M$9 -> 2 | N9: =Выручка!N$9 -> 3 | O9: =Выручка!O$9 -> 4 | ... S9: =Выручка!S$9 -> 8
B11: 1. Вводные (меняйте жёлтые ячейки)
B12: Курс ₽ за $ | C12: ₽ | D12: 90 | E12: Допущение. Обновите по курсу ЦБ на дату защиты
B13: Себестоимость одного ответа героя | C13: $ | D13: 0.0005 | E13: Замер 29.10.2026: ~3,8 тыс. токенов на входе, модель z-ai/glm-5.3-flash через OpenRouter
B14: Себестоимость одного ответа героя | C14: ₽ | D14: =D12*D13 -> 0.045 | E14: Расчёт
B15: Доля DAU, пишущих герою в день | C15: % | D15: 0.25 | E15: Гипотеза, проверить в закрытой бете
B16: Сообщений в день на пишущего | C16: шт. | D16: 6 | E16: Гипотеза, проверить в закрытой бете
B17: Цена сообщения | C17: энергии | D17: 1 | E17: Как в приложении
B18: Цена главы (со 2-й главы истории) | C18: энергии | D18: 5 | E18: Решение: первая глава каждой истории бесплатна. В приложении пока не включено
B19: Пак «5 энергии» | C19: ₽ | D19: 59 | E19: Цены в рублях, как будут в магазине приложений
B20: Пак «15 энергии» | C20: ₽ | D20: 149
B21: Пак «30 энергии» (лучшая выгода) | C21: ₽ | D21: 249
B22: Доля покупок: пак 5 | C22: % | D22: 0.2 | E22: Гипотеза
B23: Доля покупок: пак 15 | C23: % | D23: 0.5 | E23: Гипотеза
B24: Доля покупок: пак 30 | C24: % | D24: 0.3 | E24: Гипотеза. Три доли должны давать 100%
B25: Средняя цена пака | C25: ₽ | D25: =D19*D22+D20*D23+D21*D24 -> 161 | E25: Расчёт
B26: Средний размер пака | C26: энергии | D26: =5*D22+15*D23+30*D24 -> 17.5 | E26: Расчёт
B27: Средняя цена одной энергии | C27: ₽ | D27: =D25/D26 -> 9.2 | E27: Расчёт
B28: Доля платящих, которые покупают энергию | C28: % | D28: 0.6 | E28: Платящие = конверсия IAP (лист «Допущения», п. 4). Гипотеза
B29: Паков энергии в месяц на такого плательщика | C29: шт. | D29: 1 | E29: Гипотеза
B30: Добавка к среднему чеку IAP за энергию | C30: ₽ | D30: =D28*D29*D25 -> 96.6 | E30: Расчёт. Уходит в лист «Выручка», строка 30
B31: Проверка: доли паков в сумме | D31: =IF(ABS(D22+D23+D24-1)<0.0001,"OK","ОШИБКА") -> OK
B32: Расход энергии на пишущего игрока в месяц | C32: энергии | D32: =D16*Дней_в_месяце*D17 -> 180
B34: 2. Помесячный расчёт (активный сценарий)
B35: MAU | C35: чел. | H35: =Выручка!H13 -> 0 | I35: =Выручка!I13 -> 0 | J35: =Выручка!J13 -> 0 | K35: =Выручка!K13 -> 0 | L35: =Выручка!L13 -> 1500 | M35: =Выручка!M13 -> 3000 | N35: =Выручка!N13 -> 5000 | O35: =Выручка!O13 -> 7000 | ... S35: =Выручка!S13 -> 20000
B36: DAU | C36: чел. | H36: =Выручка!H14 -> 0 | I36: =Выручка!I14 -> 0 | J36: =Выручка!J14 -> 0 | K36: =Выручка!K14 -> 0 | L36: =Выручка!L14 -> 450 | M36: =Выручка!M14 -> 900 | N36: =Выручка!N14 -> 1500 | O36: =Выручка!O14 -> 2100 | ... S36: =Выручка!S14 -> 6000
B37: Пишущих герою в день | C37: чел. | H37: =H36*$D$15 -> 0 | I37: =I36*$D$15 -> 0 | J37: =J36*$D$15 -> 0 | K37: =K36*$D$15 -> 0 | L37: =L36*$D$15 -> 112.5 | M37: =M36*$D$15 -> 225 | N37: =N36*$D$15 -> 375 | O37: =O36*$D$15 -> 525 | ... S37: =S36*$D$15 -> 1500
B38: Сообщений в месяц | C38: шт. | D38: =SUMIF($H$8:$S$8,"Разработка",$H38:$S38) -> 0 | E38: =SUMIF($H$8:$S$8,"Операционка",$H38:$S38) -> 992250 | F38: =SUM($H38:$S38) -> 992250 | H38: =H37*$D$16*Дней_в_месяце -> 0 | I38: =I37*$D$16*Дней_в_месяце -> 0 | J38: =J37*$D$16*Дней_в_месяце -> 0 | K38: =K37*$D$16*Дней_в_месяце -> 0 | L38: =L37*$D$16*Дней_в_месяце -> 20250 | M38: =M37*$D$16*Дней_в_месяце -> 40500 | N38: =N37*$D$16*Дней_в_месяце -> 67500 | O38: =O37*$D$16*Дней_в_месяце -> 94500 | ... S38: =S37*$D$16*Дней_в_месяце -> 270000
B39: Затраты на токены чата | C39: ₽ | D39: =SUMIF($H$8:$S$8,"Разработка",$H39:$S39) -> 0 | E39: =SUMIF($H$8:$S$8,"Операционка",$H39:$S39) -> 44651.25 | F39: =SUM($H39:$S39) -> 44651.25 | H39: =H38*$D$14 -> 0 | I39: =I38*$D$14 -> 0 | J39: =J38*$D$14 -> 0 | K39: =K38*$D$14 -> 0 | L39: =L38*$D$14 -> 911.25 | M39: =M38*$D$14 -> 1822.5 | N39: =N38*$D$14 -> 3037.5 | O39: =O38*$D$14 -> 4252.5 | ... S39: =S38*$D$14 -> 12150
B40: Затраты на токены на 1 MAU | C40: ₽ | H40: =IF(H35>0,H39/H35,0) -> 0 | I40: =IF(I35>0,I39/I35,0) -> 0 | J40: =IF(J35>0,J39/J35,0) -> 0 | K40: =IF(K35>0,K39/K35,0) -> 0 | L40: =IF(L35>0,L39/L35,0) -> 0.6075 | M40: =IF(M35>0,M39/M35,0) -> 0.6075 | N40: =IF(N35>0,N39/N35,0) -> 0.6075 | O40: =IF(O35>0,O39/O35,0) -> 0.6075 | ... S40: =IF(S35>0,S39/S35,0) -> 0.6075
B41: Платящих всего (IAP) | C41: чел. | H41: =Выручка!H29 -> 0 | I41: =Выручка!I29 -> 0 | J41: =Выручка!J29 -> 0 | K41: =Выручка!K29 -> 0 | L41: =Выручка!L29 -> 11 | M41: =Выручка!M29 -> 22 | N41: =Выручка!N29 -> 38 | O41: =Выручка!O29 -> 56 | ... S41: =Выручка!S29 -> 200
B42: Выручка от энергии (валовая) | C42: ₽ | D42: =SUMIF($H$8:$S$8,"Разработка",$H42:$S42) -> 0 | E42: =SUMIF($H$8:$S$8,"Операционка",$H42:$S42) -> 64142.4 | F42: =SUM($H42:$S42) -> 64142.4 | H42: =H41*$D$30 -> 0 | I42: =I41*$D$30 -> 0 | J42: =J41*$D$30 -> 0 | K42: =K41*$D$30 -> 0 | L42: =L41*$D$30 -> 1062.6 | M42: =M41*$D$30 -> 2125.2 | N42: =N41*$D$30 -> 3670.8 | O42: =O41*$D$30 -> 5409.6 | ... S42: =S41*$D$30 -> 19320
B43: Комиссия магазина с энергии | C43: ₽ | D43: =SUMIF($H$8:$S$8,"Разработка",$H43:$S43) -> 0 | E43: =SUMIF($H$8:$S$8,"Операционка",$H43:$S43) -> 9621.36 | F43: =SUM($H43:$S43) -> 9621.36 | H43: =H42*Комиссия_стора -> 0 | I43: =I42*Комиссия_стора -> 0 | J43: =J42*Комиссия_стора -> 0 | K43: =K42*Комиссия_стора -> 0 | L43: =L42*Комиссия_стора -> 159.39 | M43: =M42*Комиссия_стора -> 318.78 | N43: =N42*Комиссия_стора -> 550.62 | O43: =O42*Комиссия_стора -> 811.44 | ... S43: =S42*Комиссия_стора -> 2898
B44: Результат энергии: выручка − комиссия − токены | C44: ₽ | D44: =SUMIF($H$8:$S$8,"Разработка",$H44:$S44) -> 0 | E44: =SUMIF($H$8:$S$8,"Операционка",$H44:$S44) -> 9869.79 | F44: =SUM($H44:$S44) -> 9869.79 | H44: =H42-H43-H39 -> 0 | I44: =I42-I43-I39 -> 0 | J44: =J42-J43-J39 -> 0 | K44: =K42-K43-K39 -> 0 | L44: =L42-L43-L39 -> -8.04 | M44: =M42-M43-M39 -> -16.08 | N44: =N42-N43-N39 -> 82.68 | O44: =O42-O43-O39 -> 345.66 | ... S44: =S42-S43-S39 -> 4272
...

Sheet Расходы
B2: Операционные расходы (OpEx)
B3: ₽. Ставки по фазам проекта задаются в «Допущениях», п. 5; маркетинг после релиза зависит от сценария.
B5: Показатель | C5: Ед. | D5: ="Разработка"&CHAR(10)&"("&Дев_мес&" мес.)" -> Разработка (4 мес.) | E5: ="Операционка"&CHAR(10)&"("&Опер_мес&" мес.)" -> Операционка (8 мес.) | F5: ="Итого"&CHAR(10)&"12 мес." -> Итого 12 мес. | H5: =Выручка!H$5 -> Сен 2026 | I5: =Выручка!I$5 -> Окт 2026 | J5: =Выручка!J$5 -> Ноя 2026 | K5: =Выручка!K$5 -> Дек 2026 | L5: =Выручка!L$5 -> Янв 2027 | M5: =Выручка!M$5 -> Фев 2027 | N5: =Выручка!N$5 -> Мар 2027 | O5: =Выручка!O$5 -> Апр 2027 | ... S5: =Выручка!S$5 -> Авг 2027
B6: № месяца проекта | H6: =Выручка!H$6 -> 1 | I6: =Выручка!I$6 -> 2 | J6: =Выручка!J$6 -> 3 | K6: =Выручка!K$6 -> 4 | L6: =Выручка!L$6 -> 5 | M6: =Выручка!M$6 -> 6 | N6: =Выручка!N$6 -> 7 | O6: =Выручка!O$6 -> 8 | ... S6: =Выручка!S$6 -> 12
B7: Дата (начало месяца) | H7: =Выручка!H$7 -> 46266 | I7: =Выручка!I$7 -> 46296 | J7: =Выручка!J$7 -> 46327 | K7: =Выручка!K$7 -> 46357 | L7: =Выручка!L$7 -> 46388 | M7: =Выручка!M$7 -> 46419 | N7: =Выручка!N$7 -> 46447 | O7: =Выручка!O$7 -> 46478 | ... S7: =Выручка!S$7 -> 46600
B8: Фаза | H8: =Выручка!H$8 -> Разработка | I8: =Выручка!I$8 -> Разработка | J8: =Выручка!J$8 -> Разработка | K8: =Выручка!K$8 -> Разработка | L8: =Выручка!L$8 -> Операционка | M8: =Выручка!M$8 -> Операционка | N8: =Выручка!N$8 -> Операционка | O8: =Выручка!O$8 -> Операционка | ... S8: =Выручка!S$8 -> Операционка
B9: Месяцев после релиза | H9: =Выручка!H$9 -> 0 | I9: =Выручка!I$9 -> 0 | J9: =Выручка!J$9 -> 0 | K9: =Выручка!K$9 -> 0 | L9: =Выручка!L$9 -> 1 | M9: =Выручка!M$9 -> 2 | N9: =Выручка!N$9 -> 3 | O9: =Выручка!O$9 -> 4 | ... S9: =Выручка!S$9 -> 8
B11: Операционные расходы
B12: Затраты на ИИ-сервисы (контент + токены чата) | C12: ₽ | D12: =SUMIF($H$8:$S$8,"Разработка",$H$12:$S$12) -> 16000 | E12: =SUMIF($H$8:$S$8,"Операционка",$H$12:$S$12) -> 76651.25 | F12: =SUM($H$12:$S$12) -> 92651.25 | H12: =IF(H$6>=Допущения!$C$50,IF(H$8="Разработка",Зп_дев,Зп_опер),0)+Энергия!H39 -> 4000 | I12: =IF(I$6>=Допущения!$C$50,IF(I$8="Разработка",Зп_дев,Зп_опер),0)+Энергия!I39 -> 4000 | J12: =IF(J$6>=Допущения!$C$50,IF(J$8="Разработка",Зп_дев,Зп_опер),0)+Энергия!J39 -> 4000 | K12: =IF(K$6>=Допущения!$C$50,IF(K$8="Разработка",Зп_дев,Зп_опер),0)+Энергия!K39 -> 4000 | L12: =IF(L$6>=Допущения!$C$50,IF(L$8="Разработка",Зп_дев,Зп_опер),0)+Энергия!L39 -> 4911.25 | M12: =IF(M$6>=Допущения!$C$50,IF(M$8="Разработка",Зп_дев,Зп_опер),0)+Энергия!M39 -> 5822.5 | N12: =IF(N$6>=Допущения!$C$50,IF(N$8="Разработка",Зп_дев,Зп_опер),0)+Энергия!N39 -> 7037.5 | O12: =IF(O$6>=Допущения!$C$50,IF(O$8="Разработка",Зп_дев,Зп_опер),0)+Энергия!O39 -> 8252.5 | ... S12: =IF(S$6>=Допущения!$C$50,IF(S$8="Разработка",Зп_дев,Зп_опер),0)+Энергия!S39 -> 16150
B13: Поддержка серверов и хостинг | C13: ₽ | D13: =SUMIF($H$8:$S$8,"Разработка",$H$13:$S$13) -> 6000 | E13: =SUMIF($H$8:$S$8,"Операционка",$H$13:$S$13) -> 16000 | F13: =SUM($H$13:$S$13) -> 22000 | H13: =IF(H$6>=Допущения!$C$51,IF(H$8="Разработка",Серверы_дев,Серверы_опер),0) -> 0 | I13: =IF(I$6>=Допущения!$C$51,IF(I$8="Разработка",Серверы_дев,Серверы_опер),0) -> 2000 | J13: =IF(J$6>=Допущения!$C$51,IF(J$8="Разработка",Серверы_дев,Серверы_опер),0) -> 2000 | K13: =IF(K$6>=Допущения!$C$51,IF(K$8="Разработка",Серверы_дев,Серверы_опер),0) -> 2000 | L13: =IF(L$6>=Допущения!$C$51,IF(L$8="Разработка",Серверы_дев,Серверы_опер),0) -> 2000 | M13: =IF(M$6>=Допущения!$C$51,IF(M$8="Разработка",Серверы_дев,Серверы_опер),0) -> 2000 | N13: =IF(N$6>=Допущения!$C$51,IF(N$8="Разработка",Серверы_дев,Серверы_опер),0) -> 2000 | O13: =IF(O$6>=Допущения!$C$51,IF(O$8="Разработка",Серверы_дев,Серверы_опер),0) -> 2000 | ... S13: =IF(S$6>=Допущения!$C$51,IF(S$8="Разработка",Серверы_дев,Серверы_опер),0) -> 2000
B14: Бухгалтерия и юр. сопровождение | C14: ₽ | D14: =SUMIF($H$8:$S$8,"Разработка",$H$14:$S$14) -> 10000 | E14: =SUMIF($H$8:$S$8,"Операционка",$H$14:$S$14) -> 80000 | F14: =SUM($H$14:$S$14) -> 90000 | H14: =IF(H$6>=Допущения!$C$52,IF(H$8="Разработка",Бух_дев,Бух_опер),0) -> 0 | I14: =IF(I$6>=Допущения!$C$52,IF(I$8="Разработка",Бух_дев,Бух_опер),0) -> 0 | J14: =IF(J$6>=Допущения!$C$52,IF(J$8="Разработка",Бух_дев,Бух_опер),0) -> 0 | K14: =IF(K$6>=Допущения!$C$52,IF(K$8="Разработка",Бух_дев,Бух_опер),0) -> 10000 | L14: =IF(L$6>=Допущения!$C$52,IF(L$8="Разработка",Бух_дев,Бух_опер),0) -> 10000 | M14: =IF(M$6>=Допущения!$C$52,IF(M$8="Разработка",Бух_дев,Бух_опер),0) -> 10000 | N14: =IF(N$6>=Допущения!$C$52,IF(N$8="Разработка",Бух_дев,Бух_опер),0) -> 10000 | O14: =IF(O$6>=Допущения!$C$52,IF(O$8="Разработка",Бух_дев,Бух_опер),0) -> 10000 | ... S14: =IF(S$6>=Допущения!$C$52,IF(S$8="Разработка",Бух_дев,Бух_опер),0) -> 10000
B15: Маркетинг и реклама (трафик, посевы) | C15: ₽ | D15: =SUMIF($H$8:$S$8,"Разработка",$H$15:$S$15) -> 20000 | E15: =SUMIF($H$8:$S$8,"Операционка",$H$15:$S$15) -> 240000 | F15: =SUM($H$15:$S$15) -> 260000 | H15: =IF(H$6>=Допущения!$C$53,IF(H$8="Разработка",Маркетинг_дев,Сц_маркетинг),0) -> 0 | I15: =IF(I$6>=Допущения!$C$53,IF(I$8="Разработка",Маркетинг_дев,Сц_маркетинг),0) -> 0 | J15: =IF(J$6>=Допущения!$C$53,IF(J$8="Разработка",Маркетинг_дев,Сц_маркетинг),0) -> 10000 | K15: =IF(K$6>=Допущения!$C$53,IF(K$8="Разработка",Маркетинг_дев,Сц_маркетинг),0) -> 10000 | L15: =IF(L$6>=Допущения!$C$53,IF(L$8="Разработка",Маркетинг_дев,Сц_маркетинг),0) -> 30000 | M15: =IF(M$6>=Допущения!$C$53,IF(M$8="Разработка",Маркетинг_дев,Сц_маркетинг),0) -> 30000 | N15: =IF(N$6>=Допущения!$C$53,IF(N$8="Разработка",Маркетинг_дев,Сц_маркетинг),0) -> 30000 | O15: =IF(O$6>=Допущения!$C$53,IF(O$8="Разработка",Маркетинг_дев,Сц_маркетинг),0) -> 30000 | ... S15: =IF(S$6>=Допущения!$C$53,IF(S$8="Разработка",Маркетинг_дев,Сц_маркетинг),0) -> 30000
B16: ИТОГО OpEx | C16: ₽ | D16: =SUMIF($H$8:$S$8,"Разработка",$H$16:$S$16) -> 52000 | E16: =SUMIF($H$8:$S$8,"Операционка",$H$16:$S$16) -> 412651.25 | F16: =SUM($H$16:$S$16) -> 464651.25 | H16: =SUM(H12:H15) -> 4000 | I16: =SUM(I12:I15) -> 6000 | J16: =SUM(J12:J15) -> 16000 | K16: =SUM(K12:K15) -> 26000 | L16: =SUM(L12:L15) -> 46911.25 | M16: =SUM(M12:M15) -> 47822.5 | N16: =SUM(N12:N15) -> 49037.5 | O16: =SUM(O12:O15) -> 50252.5 | ... S16: =SUM(S12:S15) -> 58150
B18: Переменные расходы
B19: Комиссия магазина приложений с IAP | C19: ₽ | D19: =SUMIF($H$8:$S$8,"Разработка",$H$19:$S$19) -> 0 | E19: =SUMIF($H$8:$S$8,"Операционка",$H$19:$S$19) -> 37229.76 | F19: =SUM($H$19:$S$19) -> 37229.76 | H19: =Выручка!H31*Комиссия_стора -> 0 | I19: =Выручка!I31*Комиссия_стора -> 0 | J19: =Выручка!J31*Комиссия_стора -> 0 | K19: =Выручка!K31*Комиссия_стора -> 0 | L19: =Выручка!L31*Комиссия_стора -> 487.74 | M19: =Выручка!M31*Комиссия_стора -> 1074.48 | N19: =Выручка!N31*Комиссия_стора -> 1912.92 | O19: =Выручка!O31*Комиссия_стора -> 2903.04 | ... S19: =Выручка!S31*Комиссия_стора -> 11868
B20: В docx комиссия не учтена (ставка 0%). Ставка задаётся в «Допущениях», п. 3.
B22: Справочно
B23: Доля маркетинга в OpEx | C23: % | D23: =IF(D16<>0,D15/D16,0) -> 0.38461538 | E23: =IF(E16<>0,E15/E16,0) -> 0.58160493 | F23: =IF(F16<>0,F15/F16,0) -> 0.55955945 | H23: =IF(H16>0,H15/H16,0) -> 0 | I23: =IF(I16>0,I15/I16,0) -> 0 | J23: =IF(J16>0,J15/J16,0) -> 0.625 | K23: =IF(K16>0,K15/K16,0) -> 0.38461538 | L23: =IF(L16>0,L15/L16,0) -> 0.63950545 | M23: =IF(M16>0,M15/M16,0) -> 0.62731978 | N23: =IF(N16>0,N15/N16,0) -> 0.6117767 | O23: =IF(O16>0,O15/O16,0) -> 0.59698522 | ... S23: =IF(S16>0,S15/S16,0) -> 0.51590714

Sheet ОПиУ
B2: Отчёт о прибылях и убытках (ОПиУ / P&L)
B3: ₽. Расходы со знаком минус.
B5: Показатель | C5: Ед. | D5: ="Разработка"&CHAR(10)&"("&Дев_мес&" мес.)" -> Разработка (4 мес.) | E5: ="Операционка"&CHAR(10)&"("&Опер_мес&" мес.)" -> Операционка (8 мес.) | F5: ="Итого"&CHAR(10)&"12 мес." -> Итого 12 мес. | H5: =Выручка!H$5 -> Сен 2026 | I5: =Выручка!I$5 -> Окт 2026 | J5: =Выручка!J$5 -> Ноя 2026 | K5: =Выручка!K$5 -> Дек 2026 | L5: =Выручка!L$5 -> Янв 2027 | M5: =Выручка!M$5 -> Фев 2027 | N5: =Выручка!N$5 -> Мар 2027 | O5: =Выручка!O$5 -> Апр 2027 | ... S5: =Выручка!S$5 -> Авг 2027
B6: № месяца проекта | H6: =Выручка!H$6 -> 1 | I6: =Выручка!I$6 -> 2 | J6: =Выручка!J$6 -> 3 | K6: =Выручка!K$6 -> 4 | L6: =Выручка!L$6 -> 5 | M6: =Выручка!M$6 -> 6 | N6: =Выручка!N$6 -> 7 | O6: =Выручка!O$6 -> 8 | ... S6: =Выручка!S$6 -> 12
B7: Дата (начало месяца) | H7: =Выручка!H$7 -> 46266 | I7: =Выручка!I$7 -> 46296 | J7: =Выручка!J$7 -> 46327 | K7: =Выручка!K$7 -> 46357 | L7: =Выручка!L$7 -> 46388 | M7: =Выручка!M$7 -> 46419 | N7: =Выручка!N$7 -> 46447 | O7: =Выручка!O$7 -> 46478 | ... S7: =Выручка!S$7 -> 46600
B8: Фаза | H8: =Выручка!H$8 -> Разработка | I8: =Выручка!I$8 -> Разработка | J8: =Выручка!J$8 -> Разработка | K8: =Выручка!K$8 -> Разработка | L8: =Выручка!L$8 -> Операционка | M8: =Выручка!M$8 -> Операционка | N8: =Выручка!N$8 -> Операционка | O8: =Выручка!O$8 -> Операционка | ... S8: =Выручка!S$8 -> Операционка
B9: Месяцев после релиза | H9: =Выручка!H$9 -> 0 | I9: =Выручка!I$9 -> 0 | J9: =Выручка!J$9 -> 0 | K9: =Выручка!K$9 -> 0 | L9: =Выручка!L$9 -> 1 | M9: =Выручка!M$9 -> 2 | N9: =Выручка!N$9 -> 3 | O9: =Выручка!O$9 -> 4 | ... S9: =Выручка!S$9 -> 8
B11: Выручка
B12: Interstitial | C12: ₽ | D12: =SUMIF($H$8:$S$8,"Разработка",$H$12:$S$12) -> 0 | E12: =SUMIF($H$8:$S$8,"Операционка",$H$12:$S$12) -> 133953.75 | F12: =SUM($H$12:$S$12) -> 133953.75 | H12: =Выручка!H19 -> 0 | I12: =Выручка!I19 -> 0 | J12: =Выручка!J19 -> 0 | K12: =Выручка!K19 -> 0 | L12: =Выручка!L19 -> 2733.75 | M12: =Выручка!M19 -> 5467.5 | N12: =Выручка!N19 -> 9112.5 | O12: =Выручка!O19 -> 12757.5 | ... S12: =Выручка!S19 -> 36450
B13: Rewarded | C13: ₽ | D13: =SUMIF($H$8:$S$8,"Разработка",$H$13:$S$13) -> 0 | E13: =SUMIF($H$8:$S$8,"Операционка",$H$13:$S$13) -> 230364 | F13: =SUM($H$13:$S$13) -> 230364 | H13: =Выручка!H25 -> 0 | I13: =Выручка!I25 -> 0 | J13: =Выручка!J25 -> 0 | K13: =Выручка!K25 -> 0 | L13: =Выручка!L25 -> 4320 | M13: =Выручка!M25 -> 8748 | N13: =Выручка!N25 -> 14940 | O13: =Выручка!O25 -> 21420 | ... S13: =Выручка!S25 -> 64800
B14: IAP (внутриигровые покупки) | C14: ₽ | D14: =SUMIF($H$8:$S$8,"Разработка",$H$14:$S$14) -> 0 | E14: =SUMIF($H$8:$S$8,"Операционка",$H$14:$S$14) -> 248198.4 | F14: =SUM($H$14:$S$14) -> 248198.4 | H14: =Выручка!H31 -> 0 | I14: =Выручка!I31 -> 0 | J14: =Выручка!J31 -> 0 | K14: =Выручка!K31 -> 0 | L14: =Выручка!L31 -> 3251.6 | M14: =Выручка!M31 -> 7163.2 | N14: =Выручка!N31 -> 12752.8 | O14: =Выручка!O31 -> 19353.6 | ... S14: =Выручка!S31 -> 79120
B15: 1. Выручка | C15: ₽ | D15: =SUMIF($H$8:$S$8,"Разработка",$H$15:$S$15) -> 0 | E15: =SUMIF($H$8:$S$8,"Операционка",$H$15:$S$15) -> 612516.15 | F15: =SUM($H$15:$S$15) -> 612516.15 | H15: =SUM(H12:H14) -> 0 | I15: =SUM(I12:I14) -> 0 | J15: =SUM(J12:J14) -> 0 | K15: =SUM(K12:K14) -> 0 | L15: =SUM(L12:L14) -> 10305.35 | M15: =SUM(M12:M14) -> 21378.7 | N15: =SUM(N12:N14) -> 36805.3 | O15: =SUM(O12:O14) -> 53531.1 | ... S15: =SUM(S12:S14) -> 180370
B16: Комиссия магазина приложений | C16: ₽ | D16: =SUMIF($H$8:$S$8,"Разработка",$H$16:$S$16) -> 0 | E16: =SUMIF($H$8:$S$8,"Операционка",$H$16:$S$16) -> -37229.76 | F16: =SUM($H$16:$S$16) -> -37229.76 | H16: =-Расходы!H19 -> 0 | I16: =-Расходы!I19 -> 0 | J16: =-Расходы!J19 -> 0 | K16: =-Расходы!K19 -> 0 | L16: =-Расходы!L19 -> -487.74 | M16: =-Расходы!M19 -> -1074.48 | N16: =-Расходы!N19 -> -1912.92 | O16: =-Расходы!O19 -> -2903.04 | ... S16: =-Расходы!S19 -> -11868
B17: 2. Валовая прибыль | C17: ₽ | D17: =SUMIF($H$8:$S$8,"Разработка",$H$17:$S$17) -> 0 | E17: =SUMIF($H$8:$S$8,"Операционка",$H$17:$S$17) -> 575286.39 | F17: =SUM($H$17:$S$17) -> 575286.39 | H17: =H15+H16 -> 0 | I17: =I15+I16 -> 0 | J17: =J15+J16 -> 0 | K17: =K15+K16 -> 0 | L17: =L15+L16 -> 9817.61 | M17: =M15+M16 -> 20304.22 | N17: =N15+N16 -> 34892.38 | O17: =O15+O16 -> 50628.06 | ... S17: =S15+S16 -> 168502
B19: Операционные расходы
B20: Затраты на ИИ-сервисы | C20: ₽ | D20: =SUMIF($H$8:$S$8,"Разработка",$H$20:$S$20) -> -16000 | E20: =SUMIF($H$8:$S$8,"Операционка",$H$20:$S$20) -> -76651.25 | F20: =SUM($H$20:$S$20) -> -92651.25 | H20: =-Расходы!H12 -> -4000 | I20: =-Расходы!I12 -> -4000 | J20: =-Расходы!J12 -> -4000 | K20: =-Расходы!K12 -> -4000 | L20: =-Расходы!L12 -> -4911.25 | M20: =-Расходы!M12 -> -5822.5 | N20: =-Расходы!N12 -> -7037.5 | O20: =-Расходы!O12 -> -8252.5 | ... S20: =-Расходы!S12 -> -16150
B21: Поддержка серверов и хостинг | C21: ₽ | D21: =SUMIF($H$8:$S$8,"Разработка",$H$21:$S$21) -> -6000 | E21: =SUMIF($H$8:$S$8,"Операционка",$H$21:$S$21) -> -16000 | F21: =SUM($H$21:$S$21) -> -22000 | H21: =-Расходы!H13 -> 0 | I21: =-Расходы!I13 -> -2000 | J21: =-Расходы!J13 -> -2000 | K21: =-Расходы!K13 -> -2000 | L21: =-Расходы!L13 -> -2000 | M21: =-Расходы!M13 -> -2000 | N21: =-Расходы!N13 -> -2000 | O21: =-Расходы!O13 -> -2000 | ... S21: =-Расходы!S13 -> -2000
B22: Бухгалтерия и юр. сопровождение | C22: ₽ | D22: =SUMIF($H$8:$S$8,"Разработка",$H$22:$S$22) -> -10000 | E22: =SUMIF($H$8:$S$8,"Операционка",$H$22:$S$22) -> -80000 | F22: =SUM($H$22:$S$22) -> -90000 | H22: =-Расходы!H14 -> 0 | I22: =-Расходы!I14 -> 0 | J22: =-Расходы!J14 -> 0 | K22: =-Расходы!K14 -> -10000 | L22: =-Расходы!L14 -> -10000 | M22: =-Расходы!M14 -> -10000 | N22: =-Расходы!N14 -> -10000 | O22: =-Расходы!O14 -> -10000 | ... S22: =-Расходы!S14 -> -10000
B23: Маркетинг и реклама | C23: ₽ | D23: =SUMIF($H$8:$S$8,"Разработка",$H$23:$S$23) -> -20000 | E23: =SUMIF($H$8:$S$8,"Операционка",$H$23:$S$23) -> -240000 | F23: =SUM($H$23:$S$23) -> -260000 | H23: =-Расходы!H15 -> 0 | I23: =-Расходы!I15 -> 0 | J23: =-Расходы!J15 -> -10000 | K23: =-Расходы!K15 -> -10000 | L23: =-Расходы!L15 -> -30000 | M23: =-Расходы!M15 -> -30000 | N23: =-Расходы!N15 -> -30000 | O23: =-Расходы!O15 -> -30000 | ... S23: =-Расходы!S15 -> -30000
B24: 3. Операционные расходы (OpEx) | C24: ₽ | D24: =SUMIF($H$8:$S$8,"Разработка",$H$24:$S$24) -> -52000 | E24: =SUMIF($H$8:$S$8,"Операционка",$H$24:$S$24) -> -412651.25 | F24: =SUM($H$24:$S$24) -> -464651.25 | H24: =SUM(H20:H23) -> -4000 | I24: =SUM(I20:I23) -> -6000 | J24: =SUM(J20:J23) -> -16000 | K24: =SUM(K20:K23) -> -26000 | L24: =SUM(L20:L23) -> -46911.25 | M24: =SUM(M20:M23) -> -47822.5 | N24: =SUM(N20:N23) -> -49037.5 | O24: =SUM(O20:O23) -> -50252.5 | ... S24: =SUM(S20:S23) -> -58150
B26: 4. EBITDA (прибыль до процентов и налогов) | C26: ₽ | D26: =SUMIF($H$8:$S$8,"Разработка",$H$26:$S$26) -> -52000 | E26: =SUMIF($H$8:$S$8,"Операционка",$H$26:$S$26) -> 162635.14 | F26: =SUM($H$26:$S$26) -> 110635.14 | H26: =H17+H24 -> -4000 | I26: =I17+I24 -> -6000 | J26: =J17+J24 -> -16000 | K26: =K17+K24 -> -26000 | L26: =L17+L24 -> -37093.64 | M26: =M17+M24 -> -27518.28 | N26: =N17+N24 -> -14145.12 | O26: =O17+O24 -> 375.56 | ... S26: =S17+S24 -> 110352
B27: Рентабельность по EBITDA | C27: % | D27: =IF(D15<>0,D26/D15,0) -> 0 | E27: =IF(E15<>0,E26/E15,0) -> 0.26551976 | F27: =IF(F15<>0,F26/F15,0) -> 0.18062404 | H27: =IF(H15>0,H26/H15,0) -> 0 | I27: =IF(I15>0,I26/I15,0) -> 0 | J27: =IF(J15>0,J26/J15,0) -> 0 | K27: =IF(K15>0,K26/K15,0) -> 0 | L27: =IF(L15>0,L26/L15,0) -> -3.5994547 | M27: =IF(M15>0,M26/M15,0) -> -1.2871821 | N27: =IF(N15>0,N26/N15,0) -> -0.38432291 | O27: =IF(O15>0,O26/O15,0) -> 0.0070157348 | ... S27: =IF(S15>0,S26/S15,0) -> 0.61180906
B28: 5. Проценты по кредиту | C28: ₽ | D28: =SUMIF($H$8:$S$8,"Разработка",$H$28:$S$28) -> 0 | E28: =SUMIF($H$8:$S$8,"Операционка",$H$28:$S$28) -> 0 | F28: =SUM($H$28:$S$28) -> 0 | H28: =0 -> 0 | I28: =0 -> 0 | J28: =0 -> 0 | K28: =0 -> 0 | L28: =0 -> 0 | M28: =0 -> 0 | N28: =0 -> 0 | O28: =0 -> 0 | ... S28: =0 -> 0
B29: 5. Прибыль до налогообложения | C29: ₽ | D29: =SUMIF($H$8:$S$8,"Разработка",$H$29:$S$29) -> -52000 | E29: =SUMIF($H$8:$S$8,"Операционка",$H$29:$S$29) -> 162635.14 | F29: =SUM($H$29:$S$29) -> 110635.14 | H29: =H26+H28 -> -4000 | I29: =I26+I28 -> -6000 | J29: =J26+J28 -> -16000 | K29: =K26+K28 -> -26000 | L29: =L26+L28 -> -37093.64 | M29: =M26+M28 -> -27518.28 | N29: =N26+N28 -> -14145.12 | O29: =O26+O28 -> 375.56 | ... S29: =S26+S28 -> 110352
B30: 6. Налог (УСН) | C30: ₽ | D30: =SUMIF($H$8:$S$8,"Разработка",$H$30:$S$30) -> 0 | E30: =SUMIF($H$8:$S$8,"Операционка",$H$30:$S$30) -> 0 | F30: =SUM($H$30:$S$30) -> 0 | H30: =-H41 -> 0 | I30: =-I41 -> 0 | J30: =-J41 -> 0 | K30: =-K41 -> 0 | L30: =-L41 -> 0 | M30: =-M41 -> 0 | N30: =-N41 -> 0 | O30: =-O41 -> 0 | ... S30: =-S41 -> 0
B31: 7. ЧИСТАЯ ПРИБЫЛЬ | C31: ₽ | D31: =SUMIF($H$8:$S$8,"Разработка",$H$31:$S$31) -> -52000 | E31: =SUMIF($H$8:$S$8,"Операционка",$H$31:$S$31) -> 162635.14 | F31: =SUM($H$31:$S$31) -> 110635.14 | H31: =H29+H30 -> -4000 | I31: =I29+I30 -> -6000 | J31: =J29+J30 -> -16000 | K31: =K29+K30 -> -26000 | L31: =L29+L30 -> -37093.64 | M31: =M29+M30 -> -27518.28 | N31: =N29+N30 -> -14145.12 | O31: =O29+O30 -> 375.56 | ... S31: =S29+S30 -> 110352
B32: Рентабельность по чистой прибыли | C32: % | D32: =IF(D15<>0,D31/D15,0) -> 0 | E32: =IF(E15<>0,E31/E15,0) -> 0.26551976 | F32: =IF(F15<>0,F31/F15,0) -> 0.18062404 | H32: =IF(H15>0,H31/H15,0) -> 0 | I32: =IF(I15>0,I31/I15,0) -> 0 | J32: =IF(J15>0,J31/J15,0) -> 0 | K32: =IF(K15>0,K31/K15,0) -> 0 | L32: =IF(L15>0,L31/L15,0) -> -3.5994547 | M32: =IF(M15>0,M31/M15,0) -> -1.2871821 | N32: =IF(N15>0,N31/N15,0) -> -0.38432291 | O32: =IF(O15>0,O31/O15,0) -> 0.0070157348 | ... S32: =IF(S15>0,S31/S15,0) -> 0.61180906
B33: Накопленная чистая прибыль | C33: ₽ | D33: =INDEX($H$33:$S$33,1,Дев_мес) -> -52000 | E33: =IF(Опер_мес>0,S33,"") -> 110635.14 | F33: =S33 -> 110635.14 | H33: =H31 -> -4000 | I33: =H33+I31 -> -10000 | J33: =I33+J31 -> -26000 | K33: =J33+K31 -> -52000 | L33: =K33+L31 -> -89093.64 | M33: =L33+M31 -> -116611.92 | N33: =M33+N31 -> -130757.04 | O33: =N33+O31 -> -130381.48 | P33: =O33+P31 -> -114308.46 | ... S33: =R33+S31 -> 110635.14
B35: Расчёт налога УСН «Доходы» (нарастающим итогом за календарный год)
